[2024-12-26T19:57:54.220+0000] {local_task_job_runner.py:120} INFO - ::group::Pre task execution logs
[2024-12-26T19:57:54.239+0000] {taskinstance.py:2076} INFO - Dependencies all met for dep_context=non-requeueable deps ti=<TaskInstance: file_sensor.my_file_sensor_task scheduled__2024-12-25T00:00:00+00:00 [queued]>
[2024-12-26T19:57:54.247+0000] {taskinstance.py:2076} INFO - Dependencies all met for dep_context=requeueable deps ti=<TaskInstance: file_sensor.my_file_sensor_task scheduled__2024-12-25T00:00:00+00:00 [queued]>
[2024-12-26T19:57:54.247+0000] {taskinstance.py:2306} INFO - Starting attempt 1 of 1
[2024-12-26T19:57:54.258+0000] {taskinstance.py:2330} INFO - Executing <Task(FileSensor): my_file_sensor_task> on 2024-12-25 00:00:00+00:00
[2024-12-26T19:57:54.265+0000] {warnings.py:112} WARNING - /home/***/.local/lib/python3.12/site-packages/***/task/task_runner/standard_task_runner.py:61: DeprecationWarning: This process (pid=1299) is multi-threaded, use of fork() may lead to deadlocks in the child.
  pid = os.fork()

[2024-12-26T19:57:54.266+0000] {standard_task_runner.py:63} INFO - Started process 1300 to run task
[2024-12-26T19:57:54.266+0000] {standard_task_runner.py:90} INFO - Running: ['***', 'tasks', 'run', 'file_sensor', 'my_file_sensor_task', 'scheduled__2024-12-25T00:00:00+00:00', '--job-id', '1130', '--raw', '--subdir', 'DAGS_FOLDER/dag_file_sensor.py', '--cfg-path', '/tmp/tmpghul0hcd']
[2024-12-26T19:57:54.267+0000] {standard_task_runner.py:91} INFO - Job 1130: Subtask my_file_sensor_task
[2024-12-26T19:57:54.300+0000] {task_command.py:426} INFO - Running <TaskInstance: file_sensor.my_file_sensor_task scheduled__2024-12-25T00:00:00+00:00 [running]> on host 87a1e11545b0
[2024-12-26T19:57:54.361+0000] {taskinstance.py:2648} INFO - Exporting env vars: AIRFLOW_CTX_DAG_OWNER='***' AIRFLOW_CTX_DAG_ID='file_sensor' AIRFLOW_CTX_TASK_ID='my_file_sensor_task' AIRFLOW_CTX_EXECUTION_DATE='2024-12-25T00:00:00+00:00' AIRFLOW_CTX_TRY_NUMBER='1' AIRFLOW_CTX_DAG_RUN_ID='scheduled__2024-12-25T00:00:00+00:00'
[2024-12-26T19:57:54.362+0000] {taskinstance.py:430} INFO - ::endgroup::
[2024-12-26T19:57:54.371+0000] {baseoperator.py:400} WARNING - FileSensor.execute cannot be called outside TaskInstance!
[2024-12-26T19:57:54.378+0000] {taskinstance.py:441} INFO - ::group::Post task execution logs
[2024-12-26T19:57:54.387+0000] {taskinstance.py:2905} ERROR - Task failed with exception
Traceback (most recent call last):
  File "/home/airflow/.local/lib/python3.12/site-packages/airflow/models/taskinstance.py", line 465, in _execute_task
    result = _execute_callable(context=context, **execute_callable_kwargs)
             ^^^^^^^^^^^^^^^^^^^^^^^^^^^^^^^^^^^^^^^^^^^^^^^^^^^^^^^^^^^^^
  File "/home/airflow/.local/lib/python3.12/site-packages/airflow/models/taskinstance.py", line 432, in _execute_callable
    return execute_callable(context=context, **execute_callable_kwargs)
           ^^^^^^^^^^^^^^^^^^^^^^^^^^^^^^^^^^^^^^^^^^^^^^^^^^^^^^^^^^^^
  File "/home/airflow/.local/lib/python3.12/site-packages/airflow/models/baseoperator.py", line 401, in wrapper
    return func(self, *args, **kwargs)
           ^^^^^^^^^^^^^^^^^^^^^^^^^^^
  File "/home/airflow/.local/lib/python3.12/site-packages/airflow/sensors/filesystem.py", line 99, in execute
    super().execute(context=context)
  File "/home/airflow/.local/lib/python3.12/site-packages/airflow/models/baseoperator.py", line 401, in wrapper
    return func(self, *args, **kwargs)
           ^^^^^^^^^^^^^^^^^^^^^^^^^^^
  File "/home/airflow/.local/lib/python3.12/site-packages/airflow/sensors/base.py", line 264, in execute
    raise e
  File "/home/airflow/.local/lib/python3.12/site-packages/airflow/sensors/base.py", line 246, in execute
    poke_return = self.poke(context)
                  ^^^^^^^^^^^^^^^^^^
  File "/home/airflow/.local/lib/python3.12/site-packages/airflow/sensors/filesystem.py", line 85, in poke
    self.log.info("Poking for file %s", self.path)
                                        ^^^^^^^^^
  File "/usr/local/lib/python3.12/functools.py", line 995, in __get__
    val = self.func(instance)
          ^^^^^^^^^^^^^^^^^^^
  File "/home/airflow/.local/lib/python3.12/site-packages/airflow/sensors/filesystem.py", line 79, in path
    hook = FSHook(self.fs_conn_id)
           ^^^^^^^^^^^^^^^^^^^^^^^
  File "/home/airflow/.local/lib/python3.12/site-packages/airflow/hooks/filesystem.py", line 64, in __init__
    conn = self.get_connection(fs_conn_id)
           ^^^^^^^^^^^^^^^^^^^^^^^^^^^^^^^
  File "/home/airflow/.local/lib/python3.12/site-packages/airflow/hooks/base.py", line 83, in get_connection
    conn = Connection.get_connection_from_secrets(conn_id)
           ^^^^^^^^^^^^^^^^^^^^^^^^^^^^^^^^^^^^^^^^^^^^^^^
  File "/home/airflow/.local/lib/python3.12/site-packages/airflow/models/connection.py", line 519, in get_connection_from_secrets
    raise AirflowNotFoundException(f"The conn_id `{conn_id}` isn't defined")
airflow.exceptions.AirflowNotFoundException: The conn_id `fs_default` isn't defined
[2024-12-26T19:57:54.391+0000] {taskinstance.py:1206} INFO - Marking task as FAILED. dag_id=file_sensor, task_id=my_file_sensor_task, run_id=scheduled__2024-12-25T00:00:00+00:00, execution_date=20241225T000000, start_date=20241226T195754, end_date=20241226T195754
[2024-12-26T19:57:54.400+0000] {standard_task_runner.py:110} ERROR - Failed to execute job 1130 for task my_file_sensor_task (The conn_id `fs_default` isn't defined; 1300)
[2024-12-26T19:57:54.439+0000] {local_task_job_runner.py:240} INFO - Task exited with return code 1
[2024-12-26T19:57:54.468+0000] {taskinstance.py:3503} INFO - 0 downstream tasks scheduled from follow-on schedule check
[2024-12-26T19:57:54.470+0000] {local_task_job_runner.py:222} INFO - ::endgroup::
[2024-12-26T19:59:38.211+0000] {local_task_job_runner.py:120} INFO - ::group::Pre task execution logs
[2024-12-26T19:59:38.287+0000] {taskinstance.py:2076} INFO - Dependencies all met for dep_context=non-requeueable deps ti=<TaskInstance: file_sensor.my_file_sensor_task scheduled__2024-12-25T00:00:00+00:00 [queued]>
[2024-12-26T19:59:38.310+0000] {taskinstance.py:2076} INFO - Dependencies all met for dep_context=requeueable deps ti=<TaskInstance: file_sensor.my_file_sensor_task scheduled__2024-12-25T00:00:00+00:00 [queued]>
[2024-12-26T19:59:38.310+0000] {taskinstance.py:2306} INFO - Starting attempt 1 of 1
[2024-12-26T19:59:38.345+0000] {taskinstance.py:2330} INFO - Executing <Task(FileSensor): my_file_sensor_task> on 2024-12-25 00:00:00+00:00
[2024-12-26T19:59:38.355+0000] {warnings.py:112} WARNING - /home/***/.local/lib/python3.12/site-packages/***/task/task_runner/standard_task_runner.py:61: DeprecationWarning: This process (pid=1330) is multi-threaded, use of fork() may lead to deadlocks in the child.
  pid = os.fork()

[2024-12-26T19:59:38.357+0000] {standard_task_runner.py:63} INFO - Started process 1332 to run task
[2024-12-26T19:59:38.359+0000] {standard_task_runner.py:90} INFO - Running: ['***', 'tasks', 'run', 'file_sensor', 'my_file_sensor_task', 'scheduled__2024-12-25T00:00:00+00:00', '--job-id', '1132', '--raw', '--subdir', 'DAGS_FOLDER/dag_file_sensor.py', '--cfg-path', '/tmp/tmpgyomv2tf']
[2024-12-26T19:59:38.361+0000] {standard_task_runner.py:91} INFO - Job 1132: Subtask my_file_sensor_task
[2024-12-26T19:59:38.441+0000] {task_command.py:426} INFO - Running <TaskInstance: file_sensor.my_file_sensor_task scheduled__2024-12-25T00:00:00+00:00 [running]> on host 87a1e11545b0
[2024-12-26T19:59:38.635+0000] {taskinstance.py:2648} INFO - Exporting env vars: AIRFLOW_CTX_DAG_OWNER='***' AIRFLOW_CTX_DAG_ID='file_sensor' AIRFLOW_CTX_TASK_ID='my_file_sensor_task' AIRFLOW_CTX_EXECUTION_DATE='2024-12-25T00:00:00+00:00' AIRFLOW_CTX_TRY_NUMBER='1' AIRFLOW_CTX_DAG_RUN_ID='scheduled__2024-12-25T00:00:00+00:00'
[2024-12-26T19:59:38.636+0000] {taskinstance.py:430} INFO - ::endgroup::
[2024-12-26T19:59:38.654+0000] {baseoperator.py:400} WARNING - FileSensor.execute cannot be called outside TaskInstance!
[2024-12-26T19:59:38.661+0000] {taskinstance.py:441} INFO - ::group::Post task execution logs
[2024-12-26T19:59:38.673+0000] {taskinstance.py:2905} ERROR - Task failed with exception
Traceback (most recent call last):
  File "/home/airflow/.local/lib/python3.12/site-packages/airflow/models/taskinstance.py", line 465, in _execute_task
    result = _execute_callable(context=context, **execute_callable_kwargs)
             ^^^^^^^^^^^^^^^^^^^^^^^^^^^^^^^^^^^^^^^^^^^^^^^^^^^^^^^^^^^^^
  File "/home/airflow/.local/lib/python3.12/site-packages/airflow/models/taskinstance.py", line 432, in _execute_callable
    return execute_callable(context=context, **execute_callable_kwargs)
           ^^^^^^^^^^^^^^^^^^^^^^^^^^^^^^^^^^^^^^^^^^^^^^^^^^^^^^^^^^^^
  File "/home/airflow/.local/lib/python3.12/site-packages/airflow/models/baseoperator.py", line 401, in wrapper
    return func(self, *args, **kwargs)
           ^^^^^^^^^^^^^^^^^^^^^^^^^^^
  File "/home/airflow/.local/lib/python3.12/site-packages/airflow/sensors/filesystem.py", line 99, in execute
    super().execute(context=context)
  File "/home/airflow/.local/lib/python3.12/site-packages/airflow/models/baseoperator.py", line 401, in wrapper
    return func(self, *args, **kwargs)
           ^^^^^^^^^^^^^^^^^^^^^^^^^^^
  File "/home/airflow/.local/lib/python3.12/site-packages/airflow/sensors/base.py", line 264, in execute
    raise e
  File "/home/airflow/.local/lib/python3.12/site-packages/airflow/sensors/base.py", line 246, in execute
    poke_return = self.poke(context)
                  ^^^^^^^^^^^^^^^^^^
  File "/home/airflow/.local/lib/python3.12/site-packages/airflow/sensors/filesystem.py", line 85, in poke
    self.log.info("Poking for file %s", self.path)
                                        ^^^^^^^^^
  File "/usr/local/lib/python3.12/functools.py", line 995, in __get__
    val = self.func(instance)
          ^^^^^^^^^^^^^^^^^^^
  File "/home/airflow/.local/lib/python3.12/site-packages/airflow/sensors/filesystem.py", line 79, in path
    hook = FSHook(self.fs_conn_id)
           ^^^^^^^^^^^^^^^^^^^^^^^
  File "/home/airflow/.local/lib/python3.12/site-packages/airflow/hooks/filesystem.py", line 64, in __init__
    conn = self.get_connection(fs_conn_id)
           ^^^^^^^^^^^^^^^^^^^^^^^^^^^^^^^
  File "/home/airflow/.local/lib/python3.12/site-packages/airflow/hooks/base.py", line 83, in get_connection
    conn = Connection.get_connection_from_secrets(conn_id)
           ^^^^^^^^^^^^^^^^^^^^^^^^^^^^^^^^^^^^^^^^^^^^^^^
  File "/home/airflow/.local/lib/python3.12/site-packages/airflow/models/connection.py", line 519, in get_connection_from_secrets
    raise AirflowNotFoundException(f"The conn_id `{conn_id}` isn't defined")
airflow.exceptions.AirflowNotFoundException: The conn_id `fs_default` isn't defined
[2024-12-26T19:59:38.680+0000] {taskinstance.py:1206} INFO - Marking task as FAILED. dag_id=file_sensor, task_id=my_file_sensor_task, run_id=scheduled__2024-12-25T00:00:00+00:00, execution_date=20241225T000000, start_date=20241226T195938, end_date=20241226T195938
[2024-12-26T19:59:38.710+0000] {standard_task_runner.py:110} ERROR - Failed to execute job 1132 for task my_file_sensor_task (The conn_id `fs_default` isn't defined; 1332)
[2024-12-26T19:59:38.739+0000] {local_task_job_runner.py:240} INFO - Task exited with return code 1
[2024-12-26T19:59:38.769+0000] {taskinstance.py:3503} INFO - 0 downstream tasks scheduled from follow-on schedule check
[2024-12-26T19:59:38.773+0000] {local_task_job_runner.py:222} INFO - ::endgroup::
