[2024-12-29T18:36:17.141+0000] {local_task_job_runner.py:120} INFO - ::group::Pre task execution logs
[2024-12-29T18:36:17.319+0000] {taskinstance.py:2076} INFO - Dependencies all met for dep_context=non-requeueable deps ti=<TaskInstance: file_sensor.my_file_sensor_task scheduled__2024-12-27T00:00:00+00:00 [queued]>
[2024-12-29T18:36:17.409+0000] {taskinstance.py:2076} INFO - Dependencies all met for dep_context=requeueable deps ti=<TaskInstance: file_sensor.my_file_sensor_task scheduled__2024-12-27T00:00:00+00:00 [queued]>
[2024-12-29T18:36:17.417+0000] {taskinstance.py:2306} INFO - Starting attempt 1 of 1
[2024-12-29T18:36:17.561+0000] {taskinstance.py:2330} INFO - Executing <Task(FileSensor): my_file_sensor_task> on 2024-12-27 00:00:00+00:00
[2024-12-29T18:36:17.648+0000] {warnings.py:112} WARNING - /home/***/.local/lib/python3.12/site-packages/***/task/task_runner/standard_task_runner.py:61: DeprecationWarning: This process (pid=64) is multi-threaded, use of fork() may lead to deadlocks in the child.
  pid = os.fork()

[2024-12-29T18:36:17.653+0000] {standard_task_runner.py:63} INFO - Started process 81 to run task
[2024-12-29T18:36:17.654+0000] {standard_task_runner.py:90} INFO - Running: ['***', 'tasks', 'run', 'file_sensor', 'my_file_sensor_task', 'scheduled__2024-12-27T00:00:00+00:00', '--job-id', '1143', '--raw', '--subdir', 'DAGS_FOLDER/dag_file_sensor.py', '--cfg-path', '/tmp/tmp4nogzp28']
[2024-12-29T18:36:17.655+0000] {standard_task_runner.py:91} INFO - Job 1143: Subtask my_file_sensor_task
[2024-12-29T18:36:17.882+0000] {task_command.py:426} INFO - Running <TaskInstance: file_sensor.my_file_sensor_task scheduled__2024-12-27T00:00:00+00:00 [running]> on host 87a1e11545b0
[2024-12-29T18:36:18.514+0000] {taskinstance.py:2648} INFO - Exporting env vars: AIRFLOW_CTX_DAG_OWNER='***' AIRFLOW_CTX_DAG_ID='file_sensor' AIRFLOW_CTX_TASK_ID='my_file_sensor_task' AIRFLOW_CTX_EXECUTION_DATE='2024-12-27T00:00:00+00:00' AIRFLOW_CTX_TRY_NUMBER='1' AIRFLOW_CTX_DAG_RUN_ID='scheduled__2024-12-27T00:00:00+00:00'
[2024-12-29T18:36:18.515+0000] {taskinstance.py:430} INFO - ::endgroup::
[2024-12-29T18:36:18.617+0000] {baseoperator.py:400} WARNING - FileSensor.execute cannot be called outside TaskInstance!
[2024-12-29T18:36:18.662+0000] {taskinstance.py:441} INFO - ::group::Post task execution logs
[2024-12-29T18:36:18.704+0000] {taskinstance.py:2905} ERROR - Task failed with exception
Traceback (most recent call last):
  File "/home/airflow/.local/lib/python3.12/site-packages/airflow/models/taskinstance.py", line 465, in _execute_task
    result = _execute_callable(context=context, **execute_callable_kwargs)
             ^^^^^^^^^^^^^^^^^^^^^^^^^^^^^^^^^^^^^^^^^^^^^^^^^^^^^^^^^^^^^
  File "/home/airflow/.local/lib/python3.12/site-packages/airflow/models/taskinstance.py", line 432, in _execute_callable
    return execute_callable(context=context, **execute_callable_kwargs)
           ^^^^^^^^^^^^^^^^^^^^^^^^^^^^^^^^^^^^^^^^^^^^^^^^^^^^^^^^^^^^
  File "/home/airflow/.local/lib/python3.12/site-packages/airflow/models/baseoperator.py", line 401, in wrapper
    return func(self, *args, **kwargs)
           ^^^^^^^^^^^^^^^^^^^^^^^^^^^
  File "/home/airflow/.local/lib/python3.12/site-packages/airflow/sensors/filesystem.py", line 99, in execute
    super().execute(context=context)
  File "/home/airflow/.local/lib/python3.12/site-packages/airflow/models/baseoperator.py", line 401, in wrapper
    return func(self, *args, **kwargs)
           ^^^^^^^^^^^^^^^^^^^^^^^^^^^
  File "/home/airflow/.local/lib/python3.12/site-packages/airflow/sensors/base.py", line 264, in execute
    raise e
  File "/home/airflow/.local/lib/python3.12/site-packages/airflow/sensors/base.py", line 246, in execute
    poke_return = self.poke(context)
                  ^^^^^^^^^^^^^^^^^^
  File "/home/airflow/.local/lib/python3.12/site-packages/airflow/sensors/filesystem.py", line 85, in poke
    self.log.info("Poking for file %s", self.path)
                                        ^^^^^^^^^
  File "/usr/local/lib/python3.12/functools.py", line 995, in __get__
    val = self.func(instance)
          ^^^^^^^^^^^^^^^^^^^
  File "/home/airflow/.local/lib/python3.12/site-packages/airflow/sensors/filesystem.py", line 79, in path
    hook = FSHook(self.fs_conn_id)
           ^^^^^^^^^^^^^^^^^^^^^^^
  File "/home/airflow/.local/lib/python3.12/site-packages/airflow/hooks/filesystem.py", line 64, in __init__
    conn = self.get_connection(fs_conn_id)
           ^^^^^^^^^^^^^^^^^^^^^^^^^^^^^^^
  File "/home/airflow/.local/lib/python3.12/site-packages/airflow/hooks/base.py", line 83, in get_connection
    conn = Connection.get_connection_from_secrets(conn_id)
           ^^^^^^^^^^^^^^^^^^^^^^^^^^^^^^^^^^^^^^^^^^^^^^^
  File "/home/airflow/.local/lib/python3.12/site-packages/airflow/models/connection.py", line 519, in get_connection_from_secrets
    raise AirflowNotFoundException(f"The conn_id `{conn_id}` isn't defined")
airflow.exceptions.AirflowNotFoundException: The conn_id `fs_default` isn't defined
[2024-12-29T18:36:18.738+0000] {taskinstance.py:1206} INFO - Marking task as FAILED. dag_id=file_sensor, task_id=my_file_sensor_task, run_id=scheduled__2024-12-27T00:00:00+00:00, execution_date=20241227T000000, start_date=20241229T183617, end_date=20241229T183618
[2024-12-29T18:36:18.789+0000] {standard_task_runner.py:110} ERROR - Failed to execute job 1143 for task my_file_sensor_task (The conn_id `fs_default` isn't defined; 81)
[2024-12-29T18:36:18.846+0000] {local_task_job_runner.py:240} INFO - Task exited with return code 1
[2024-12-29T18:36:18.933+0000] {taskinstance.py:3503} INFO - 0 downstream tasks scheduled from follow-on schedule check
[2024-12-29T18:36:18.945+0000] {local_task_job_runner.py:222} INFO - ::endgroup::
