[2024-12-29T19:33:06.330+0000] {local_task_job_runner.py:120} INFO - ::group::Pre task execution logs
[2024-12-29T19:33:06.351+0000] {taskinstance.py:2076} INFO - Dependencies all met for dep_context=non-requeueable deps ti=<TaskInstance: file_sensor.wait_for_file scheduled__2024-12-24T00:00:00+00:00 [queued]>
[2024-12-29T19:33:06.359+0000] {taskinstance.py:2076} INFO - Dependencies all met for dep_context=requeueable deps ti=<TaskInstance: file_sensor.wait_for_file scheduled__2024-12-24T00:00:00+00:00 [queued]>
[2024-12-29T19:33:06.360+0000] {taskinstance.py:2306} INFO - Starting attempt 4 of 4
[2024-12-29T19:33:06.373+0000] {taskinstance.py:2330} INFO - Executing <Task(FileSensor): wait_for_file> on 2024-12-24 00:00:00+00:00
[2024-12-29T19:33:06.377+0000] {warnings.py:112} WARNING - /home/***/.local/lib/python3.12/site-packages/***/task/task_runner/standard_task_runner.py:61: DeprecationWarning: This process (pid=890) is multi-threaded, use of fork() may lead to deadlocks in the child.
  pid = os.fork()

[2024-12-29T19:33:06.378+0000] {standard_task_runner.py:63} INFO - Started process 891 to run task
[2024-12-29T19:33:06.379+0000] {standard_task_runner.py:90} INFO - Running: ['***', 'tasks', 'run', 'file_sensor', 'wait_for_file', 'scheduled__2024-12-24T00:00:00+00:00', '--job-id', '1172', '--raw', '--subdir', 'DAGS_FOLDER/dag_file_sensor.py', '--cfg-path', '/tmp/tmpfmn4i70m']
[2024-12-29T19:33:06.380+0000] {standard_task_runner.py:91} INFO - Job 1172: Subtask wait_for_file
[2024-12-29T19:33:06.418+0000] {task_command.py:426} INFO - Running <TaskInstance: file_sensor.wait_for_file scheduled__2024-12-24T00:00:00+00:00 [running]> on host 87a1e11545b0
[2024-12-29T19:33:06.480+0000] {taskinstance.py:2648} INFO - Exporting env vars: AIRFLOW_CTX_DAG_OWNER='***' AIRFLOW_CTX_DAG_ID='file_sensor' AIRFLOW_CTX_TASK_ID='wait_for_file' AIRFLOW_CTX_EXECUTION_DATE='2024-12-24T00:00:00+00:00' AIRFLOW_CTX_TRY_NUMBER='4' AIRFLOW_CTX_DAG_RUN_ID='scheduled__2024-12-24T00:00:00+00:00'
[2024-12-29T19:33:06.481+0000] {taskinstance.py:430} INFO - ::endgroup::
[2024-12-29T19:33:06.492+0000] {baseoperator.py:400} WARNING - FileSensor.execute cannot be called outside TaskInstance!
[2024-12-29T19:33:06.498+0000] {taskinstance.py:441} INFO - ::group::Post task execution logs
[2024-12-29T19:33:06.505+0000] {taskinstance.py:2905} ERROR - Task failed with exception
Traceback (most recent call last):
  File "/home/airflow/.local/lib/python3.12/site-packages/airflow/models/taskinstance.py", line 465, in _execute_task
    result = _execute_callable(context=context, **execute_callable_kwargs)
             ^^^^^^^^^^^^^^^^^^^^^^^^^^^^^^^^^^^^^^^^^^^^^^^^^^^^^^^^^^^^^
  File "/home/airflow/.local/lib/python3.12/site-packages/airflow/models/taskinstance.py", line 432, in _execute_callable
    return execute_callable(context=context, **execute_callable_kwargs)
           ^^^^^^^^^^^^^^^^^^^^^^^^^^^^^^^^^^^^^^^^^^^^^^^^^^^^^^^^^^^^
  File "/home/airflow/.local/lib/python3.12/site-packages/airflow/models/baseoperator.py", line 401, in wrapper
    return func(self, *args, **kwargs)
           ^^^^^^^^^^^^^^^^^^^^^^^^^^^
  File "/home/airflow/.local/lib/python3.12/site-packages/airflow/sensors/filesystem.py", line 99, in execute
    super().execute(context=context)
  File "/home/airflow/.local/lib/python3.12/site-packages/airflow/models/baseoperator.py", line 401, in wrapper
    return func(self, *args, **kwargs)
           ^^^^^^^^^^^^^^^^^^^^^^^^^^^
  File "/home/airflow/.local/lib/python3.12/site-packages/airflow/sensors/base.py", line 264, in execute
    raise e
  File "/home/airflow/.local/lib/python3.12/site-packages/airflow/sensors/base.py", line 246, in execute
    poke_return = self.poke(context)
                  ^^^^^^^^^^^^^^^^^^
  File "/home/airflow/.local/lib/python3.12/site-packages/airflow/sensors/filesystem.py", line 85, in poke
    self.log.info("Poking for file %s", self.path)
                                        ^^^^^^^^^
  File "/usr/local/lib/python3.12/functools.py", line 995, in __get__
    val = self.func(instance)
          ^^^^^^^^^^^^^^^^^^^
  File "/home/airflow/.local/lib/python3.12/site-packages/airflow/sensors/filesystem.py", line 79, in path
    hook = FSHook(self.fs_conn_id)
           ^^^^^^^^^^^^^^^^^^^^^^^
  File "/home/airflow/.local/lib/python3.12/site-packages/airflow/hooks/filesystem.py", line 64, in __init__
    conn = self.get_connection(fs_conn_id)
           ^^^^^^^^^^^^^^^^^^^^^^^^^^^^^^^
  File "/home/airflow/.local/lib/python3.12/site-packages/airflow/hooks/base.py", line 83, in get_connection
    conn = Connection.get_connection_from_secrets(conn_id)
           ^^^^^^^^^^^^^^^^^^^^^^^^^^^^^^^^^^^^^^^^^^^^^^^
  File "/home/airflow/.local/lib/python3.12/site-packages/airflow/models/connection.py", line 519, in get_connection_from_secrets
    raise AirflowNotFoundException(f"The conn_id `{conn_id}` isn't defined")
airflow.exceptions.AirflowNotFoundException: The conn_id `fs_default` isn't defined
[2024-12-29T19:33:06.508+0000] {taskinstance.py:1206} INFO - Marking task as FAILED. dag_id=file_sensor, task_id=wait_for_file, run_id=scheduled__2024-12-24T00:00:00+00:00, execution_date=20241224T000000, start_date=20241229T193306, end_date=20241229T193306
[2024-12-29T19:33:06.515+0000] {standard_task_runner.py:110} ERROR - Failed to execute job 1172 for task wait_for_file (The conn_id `fs_default` isn't defined; 891)
[2024-12-29T19:33:06.551+0000] {local_task_job_runner.py:240} INFO - Task exited with return code 1
[2024-12-29T19:33:06.599+0000] {taskinstance.py:3503} INFO - 0 downstream tasks scheduled from follow-on schedule check
[2024-12-29T19:33:06.602+0000] {local_task_job_runner.py:222} INFO - ::endgroup::
